你好，我是朱晔。今天，我来和你聊聊业务代码中与数据库事务相关的坑。

Spring针对Java Transaction API (JTA)、JDBC、Hibernate和Java Persistence API (JPA)等事务API，实现了一致的编程模型，而Spring的声明式事务功能更是提供了极其方便的事务配置方式，配合Spring Boot的自动配置，大多数Spring Boot项目只需要在方法上标记@Transactional注解，即可一键开启方法的事务性配置。

据我观察，大多数业务开发同学都有事务的概念，也知道如果整体考虑多个数据库操作要么成功要么失败时，需要通过数据库事务来实现多个操作的一致性和原子性。但，在使用上大多仅限于为方法标记@Transactional，不会去关注事务是否有效、出错后事务是否正确回滚，也不会考虑复杂的业务代码中涉及多个子业务逻辑时，怎么正确处理事务。

事务没有被正确处理，一般来说不会过于影响正常流程，也不容易在测试阶段被发现。但当系统越来越复杂、压力越来越大之后，就会带来大量的数据不一致问题，随后就是大量的人工介入查看和修复数据。

所以说，一个成熟的业务系统和一个基本可用能完成功能的业务系统，在事务处理细节上的差异非常大。要确保事务的配置符合业务功能的需求，往往不仅仅是技术问题，还涉及产品流程和架构设计的问题。今天这一讲的标题“20%的业务代码的Spring声明式事务，可能都没处理正确”中，20%这个数字在我看来还是比较保守的。

我今天要分享的内容，就是帮助你在技术问题上理清思路，避免因为事务处理不当让业务逻辑的实现产生大量偶发Bug。

## 小心Spring的事务可能没有生效

在使用@Transactional注解开启声明式事务时， 第一个最容易忽略的问题是，很可能事务并没有生效。

实现下面的Demo需要一些基础类，首先定义一个具有ID和姓名属性的UserEntity，也就是一个包含两个字段的用户表：

```
@Entity
@Data
public class UserEntity {
    @Id
    @GeneratedValue(strategy = AUTO)
    private Long id;
    private String name;

    public UserEntity() { }

    public UserEntity(String name) {
        this.name = name;
    }
}
```

为了方便理解，我使用Spring JPA做数据库访问，实现这样一个Repository，新增一个根据用户名查询所有数据的方法：

```
@Repository
public interface UserRepository extends JpaRepository<UserEntity, Long> {
    List<UserEntity> findByName(String name);
}
```

定义一个UserService类，负责业务逻辑处理。如果不清楚@Transactional的实现方式，只考虑代码逻辑的话，这段代码看起来没有问题。

定义一个入口方法createUserWrong1来调用另一个私有方法createUserPrivate，私有方法上标记了@Transactional注解。当传入的用户名包含test关键字时判断为用户名不合法，抛出异常，让用户创建操作失败，期望事务可以回滚：

```
@Service
@Slf4j
public class UserService {
    @Autowired
    private UserRepository userRepository;

    //一个公共方法供Controller调用，内部调用事务性的私有方法
    public int createUserWrong1(String name) {
        try {
            this.createUserPrivate(new UserEntity(name));
        } catch (Exception ex) {
            log.error("create user failed because {}", ex.getMessage());
        }
        return userRepository.findByName(name).size();
    }

    //标记了@Transactional的private方法
    @Transactional
    private void createUserPrivate(UserEntity entity) {
        userRepository.save(entity);
        if (entity.getName().contains("test"))
            throw new RuntimeException("invalid username!");
    }

    //根据用户名查询用户数
    public int getUserCount(String name) {
        return userRepository.findByName(name).size();
    }
}
```

下面是Controller的实现，只是调用一下刚才定义的UserService中的入口方法createUserWrong1。

```
@Autowired
private UserService userService;


@GetMapping("wrong1")
public int wrong1(@RequestParam("name") String name) {
    return userService.createUserWrong1(name);
}
```

调用接口后发现，即便用户名不合法，用户也能创建成功。刷新浏览器，多次发现有十几个的非法用户注册。

这里给出@Transactional生效原则1，**除非特殊配置（比如使用AspectJ静态织入实现AOP），否则只有定义在public方法上的@Transactional才能生效**。原因是，Spring默认通过动态代理的方式实现AOP，对目标方法进行增强，private方法无法代理到，Spring自然也无法动态增强事务处理逻辑。

你可能会说，修复方式很简单，把标记了事务注解的createUserPrivate方法改为public即可。在UserService中再建一个入口方法createUserWrong2，来调用这个public方法再次尝试：

```
public int createUserWrong2(String name) {
    try {
        this.createUserPublic(new UserEntity(name));
    } catch (Exception ex) {
        log.error("create user failed because {}", ex.getMessage());
    }
	return userRepository.findByName(name).size();
}

//标记了@Transactional的public方法
@Transactional
public void createUserPublic(UserEntity entity) {
    userRepository.save(entity);
    if (entity.getName().contains("test"))
        throw new RuntimeException("invalid username!");
}
```

测试发现，调用新的createUserWrong2方法事务同样不生效。这里，我给出@Transactional生效原则2，**必须通过代理过的类从外部调用目标方法才能生效**。

Spring通过AOP技术对方法进行增强，要调用增强过的方法必然是调用代理后的对象。我们尝试修改下UserService的代码，注入一个self，然后再通过self实例调用标记有@Transactional注解的createUserPublic方法。设置断点可以看到，self是由Spring通过CGLIB方式增强过的类：

- CGLIB通过继承方式实现代理类，private方法在子类不可见，自然也就无法进行事务增强；
- this指针代表对象自己，Spring不可能注入this，所以通过this访问方法必然不是代理。

![](https://static001.geekbang.org/resource/image/b0/6c/b077c033fa394353309fbb4f8368e46c.png?wh=2146%2A1248)

把this改为self后测试发现，在Controller中调用createUserRight方法可以验证事务是生效的，非法的用户注册操作可以回滚。

虽然在UserService内部注入自己调用自己的createUserPublic可以正确实现事务，但更合理的实现方式是，让Controller直接调用之前定义的UserService的createUserPublic方法，因为注入自己调用自己很奇怪，也不符合分层实现的规范：

```
@GetMapping("right2")
public int right2(@RequestParam("name") String name) {
    try {
        userService.createUserPublic(new UserEntity(name));
    } catch (Exception ex) {
        log.error("create user failed because {}", ex.getMessage());
    }
    return userService.getUserCount(name);
}
```

我们再通过一张图来回顾下this自调用、通过self调用，以及在Controller中调用UserService三种实现的区别：

![](https://static001.geekbang.org/resource/image/c4/70/c43ea620b0b611ae194f8438506d7570.png?wh=1860%2A866)

通过this自调用，没有机会走到Spring的代理类；后两种改进方案调用的是Spring注入的UserService，通过代理调用才有机会对createUserPublic方法进行动态增强。

这里，我还有一个小技巧，**强烈建议你在开发时打开相关的Debug日志，以方便了解Spring事务实现的细节，并及时判断事务的执行情况**。

我们的Demo代码使用JPA进行数据库访问，可以这么开启Debug日志：

```
logging.level.org.springframework.orm.jpa=DEBUG
```

开启日志后，我们再比较下在UserService中通过this调用和在Controller中通过注入的UserService Bean调用createUserPublic区别。很明显，this调用因为没有走代理，事务没有在createUserPublic方法上生效，只在Repository的save方法层面生效：

```
//在UserService中通过this调用public的createUserPublic
[10:10:19.913] [http-nio-45678-exec-1] [DEBUG] [o.s.orm.jpa.JpaTransactionManager       :370 ] - Creating new transaction with name [org.springframework.data.jpa.repository.support.SimpleJpaRepository.save]: PROPAGATION_REQUIRED,ISOLATION_DEFAULT
//在Controller中通过注入的UserService Bean调用createUserPublic
[10:10:47.750] [http-nio-45678-exec-6] [DEBUG] [o.s.orm.jpa.JpaTransactionManager       :370 ] - Creating new transaction with name [org.geekbang.time.commonmistakes.transaction.demo1.UserService.createUserPublic]: PROPAGATION_REQUIRED,ISOLATION_DEFAULT
```

你可能还会考虑一个问题，这种实现在Controller里处理了异常显得有点繁琐，还不如直接把createUserWrong2方法加上@Transactional注解，然后在Controller中直接调用这个方法。这样一来，既能从外部（Controller中）调用UserService中的方法，方法又是public的能够被动态代理AOP增强。

你可以试一下这种方法，但很容易就会踩第二个坑，即因为没有正确处理异常，导致事务即便生效也不一定能回滚。

## 事务即便生效也不一定能回滚

通过AOP实现事务处理可以理解为，使用try…catch…来包裹标记了@Transactional注解的方法，**当方法出现了异常并且满足一定条件的时候**，在catch里面我们可以设置事务回滚，没有异常则直接提交事务。

这里的“一定条件”，主要包括两点。

第一，**只有异常传播出了标记了@Transactional注解的方法，事务才能回滚**。在Spring的TransactionAspectSupport里有个 invokeWithinTransaction方法，里面就是处理事务的逻辑。可以看到，只有捕获到异常才能进行后续事务处理：

```
try {
   // This is an around advice: Invoke the next interceptor in the chain.
   // This will normally result in a target object being invoked.
   retVal = invocation.proceedWithInvocation();
}
catch (Throwable ex) {
   // target invocation exception
   completeTransactionAfterThrowing(txInfo, ex);
   throw ex;
}
finally {
   cleanupTransactionInfo(txInfo);
}
```

第二，**默认情况下，出现RuntimeException（非受检异常）或Error的时候，Spring才会回滚事务**。

打开Spring的DefaultTransactionAttribute类能看到如下代码块，可以发现相关证据，通过注释也能看到Spring这么做的原因，大概的意思是受检异常一般是业务异常，或者说是类似另一种方法的返回值，出现这样的异常可能业务还能完成，所以不会主动回滚；而Error或RuntimeException代表了非预期的结果，应该回滚：

```
/**
 * The default behavior is as with EJB: rollback on unchecked exception
 * ({@link RuntimeException}), assuming an unexpected outcome outside of any
 * business rules. Additionally, we also attempt to rollback on {@link Error} which
 * is clearly an unexpected outcome as well. By contrast, a checked exception is
 * considered a business exception and therefore a regular expected outcome of the
 * transactional business method, i.e. a kind of alternative return value which
 * still allows for regular completion of resource operations.
 * <p>This is largely consistent with TransactionTemplate's default behavior,
 * except that TransactionTemplate also rolls back on undeclared checked exceptions
 * (a corner case). For declarative transactions, we expect checked exceptions to be
 * intentionally declared as business exceptions, leading to a commit by default.
 * @see org.springframework.transaction.support.TransactionTemplate#execute
 */
@Override
public boolean rollbackOn(Throwable ex) {
   return (ex instanceof RuntimeException || ex instanceof Error);
}
```

接下来，我和你分享2个反例。

重新实现一下UserService中的注册用户操作：

- 在createUserWrong1方法中会抛出一个RuntimeException，但由于方法内catch了所有异常，异常无法从方法传播出去，事务自然无法回滚。
- 在createUserWrong2方法中，注册用户的同时会有一次otherTask文件读取操作，如果文件读取失败，我们希望用户注册的数据库操作回滚。虽然这里没有捕获异常，但因为otherTask方法抛出的是受检异常，createUserWrong2传播出去的也是受检异常，事务同样不会回滚。

```
@Service
@Slf4j
public class UserService {
    @Autowired
    private UserRepository userRepository;
    
    //异常无法传播出方法，导致事务无法回滚
    @Transactional
    public void createUserWrong1(String name) {
        try {
            userRepository.save(new UserEntity(name));
            throw new RuntimeException("error");
        } catch (Exception ex) {
            log.error("create user failed", ex);
        }
    }

    //即使出了受检异常也无法让事务回滚
    @Transactional
    public void createUserWrong2(String name) throws IOException {
        userRepository.save(new UserEntity(name));
        otherTask();
    }

    //因为文件不存在，一定会抛出一个IOException
    private void otherTask() throws IOException {
        Files.readAllLines(Paths.get("file-that-not-exist"));
    }
}
```

Controller中的实现，仅仅是调用UserService的createUserWrong1和createUserWrong2方法，这里就贴出实现了。这2个方法的实现和调用，虽然完全避开了事务不生效的坑，但因为异常处理不当，导致程序没有如我们期望的文件操作出现异常时回滚事务。

现在，我们来看下修复方式，以及如何通过日志来验证是否修复成功。针对这2种情况，对应的修复方法如下。

第一，如果你希望自己捕获异常进行处理的话，也没关系，可以手动设置让当前事务处于回滚状态：

```
@Transactional
public void createUserRight1(String name) {
    try {
        userRepository.save(new UserEntity(name));
        throw new RuntimeException("error");
    } catch (Exception ex) {
        log.error("create user failed", ex);
        TransactionAspectSupport.currentTransactionStatus().setRollbackOnly();
    }
}
```

运行后可以在日志中看到Rolling back字样，确认事务回滚了。同时，我们还注意到“Transactional code has requested rollback”的提示，表明手动请求回滚：

```
[22:14:49.352] [http-nio-45678-exec-4] [DEBUG] [o.s.orm.jpa.JpaTransactionManager       :698 ] - Transactional code has requested rollback
[22:14:49.353] [http-nio-45678-exec-4] [DEBUG] [o.s.orm.jpa.JpaTransactionManager       :834 ] - Initiating transaction rollback
[22:14:49.353] [http-nio-45678-exec-4] [DEBUG] [o.s.orm.jpa.JpaTransactionManager       :555 ] - Rolling back JPA transaction on EntityManager [SessionImpl(1906719643<open>)]
```

第二，在注解中声明，期望遇到所有的Exception都回滚事务（来突破默认不回滚受检异常的限制）：

```
@Transactional(rollbackFor = Exception.class)
public void createUserRight2(String name) throws IOException {
    userRepository.save(new UserEntity(name));
    otherTask();
}
```

运行后，同样可以在日志中看到回滚的提示：

```
[22:10:47.980] [http-nio-45678-exec-4] [DEBUG] [o.s.orm.jpa.JpaTransactionManager       :834 ] - Initiating transaction rollback
[22:10:47.981] [http-nio-45678-exec-4] [DEBUG] [o.s.orm.jpa.JpaTransactionManager       :555 ] - Rolling back JPA transaction on EntityManager [SessionImpl(1419329213<open>)]
```

在这个例子中，我们展现的是一个复杂的业务逻辑，其中有数据库操作、IO操作，在IO操作出现问题时希望让数据库事务也回滚，以确保逻辑的一致性。在有些业务逻辑中，可能会包含多次数据库操作，我们不一定希望将两次操作作为一个事务来处理，这时候就需要仔细考虑事务传播的配置了，否则也可能踩坑。

## 请确认事务传播配置是否符合自己的业务逻辑

有这么一个场景：一个用户注册的操作，会插入一个主用户到用户表，还会注册一个关联的子用户。我们希望将子用户注册的数据库操作作为一个独立事务来处理，即使失败也不会影响主流程，即不影响主用户的注册。

接下来，我们模拟一个实现类似业务逻辑的UserService：

```
@Autowired
private UserRepository userRepository;

@Autowired
private SubUserService subUserService;

@Transactional
public void createUserWrong(UserEntity entity) {
    createMainUser(entity);
    subUserService.createSubUserWithExceptionWrong(entity);
}

private void createMainUser(UserEntity entity) {
    userRepository.save(entity);
    log.info("createMainUser finish");
}
```

SubUserService的createSubUserWithExceptionWrong实现正如其名，因为最后我们抛出了一个运行时异常，错误原因是用户状态无效，所以子用户的注册肯定是失败的。我们期望子用户的注册作为一个事务单独回滚，不影响主用户的注册，这样的逻辑可以实现吗？

```
@Service
@Slf4j
public class SubUserService {

    @Autowired
    private UserRepository userRepository;

    @Transactional
    public void createSubUserWithExceptionWrong(UserEntity entity) {
        log.info("createSubUserWithExceptionWrong start");
        userRepository.save(entity);
        throw new RuntimeException("invalid status");
    }
}
```

我们在Controller里实现一段测试代码，调用UserService：

```
@GetMapping("wrong")
public int wrong(@RequestParam("name") String name) {
    try {
        userService.createUserWrong(new UserEntity(name));
    } catch (Exception ex) {
        log.error("createUserWrong failed, reason:{}", ex.getMessage());
    }
    return userService.getUserCount(name);
}
```

调用后可以在日志中发现如下信息，很明显事务回滚了，最后Controller打出了创建子用户抛出的运行时异常：

```
[22:50:42.866] [http-nio-45678-exec-8] [DEBUG] [o.s.orm.jpa.JpaTransactionManager       :555 ] - Rolling back JPA transaction on EntityManager [SessionImpl(103972212<open>)]
[22:50:42.869] [http-nio-45678-exec-8] [DEBUG] [o.s.orm.jpa.JpaTransactionManager       :620 ] - Closing JPA EntityManager [SessionImpl(103972212<open>)] after transaction
[22:50:42.869] [http-nio-45678-exec-8] [ERROR] [t.d.TransactionPropagationController:23  ] - createUserWrong failed, reason:invalid status
```

你马上就会意识到，不对呀，因为运行时异常逃出了@Transactional注解标记的createUserWrong方法，Spring当然会回滚事务了。如果我们希望主方法不回滚，应该把子方法抛出的异常捕获了。

也就是这么改，把subUserService.createSubUserWithExceptionWrong包裹上catch，这样外层主方法就不会出现异常了：

```
@Transactional
public void createUserWrong2(UserEntity entity) {
    createMainUser(entity);
    try{
        subUserService.createSubUserWithExceptionWrong(entity);
    } catch (Exception ex) {
        // 虽然捕获了异常，但是因为没有开启新事务，而当前事务因为异常已经被标记为rollback了，所以最终还是会回滚。
        log.error("create sub user error:{}", ex.getMessage());
    }
}
```

运行程序后可以看到如下日志：

```
[22:57:21.722] [http-nio-45678-exec-3] [DEBUG] [o.s.orm.jpa.JpaTransactionManager       :370 ] - Creating new transaction with name [org.geekbang.time.commonmistakes.transaction.demo3.UserService.createUserWrong2]: PROPAGATION_REQUIRED,ISOLATION_DEFAULT
[22:57:21.739] [http-nio-45678-exec-3] [INFO ] [t.c.transaction.demo3.SubUserService:19  ] - createSubUserWithExceptionWrong start
[22:57:21.739] [http-nio-45678-exec-3] [DEBUG] [o.s.orm.jpa.JpaTransactionManager       :356 ] - Found thread-bound EntityManager [SessionImpl(1794007607<open>)] for JPA transaction
[22:57:21.739] [http-nio-45678-exec-3] [DEBUG] [o.s.orm.jpa.JpaTransactionManager       :471 ] - Participating in existing transaction
[22:57:21.740] [http-nio-45678-exec-3] [DEBUG] [o.s.orm.jpa.JpaTransactionManager       :843 ] - Participating transaction failed - marking existing transaction as rollback-only
[22:57:21.740] [http-nio-45678-exec-3] [DEBUG] [o.s.orm.jpa.JpaTransactionManager       :580 ] - Setting JPA transaction on EntityManager [SessionImpl(1794007607<open>)] rollback-only
[22:57:21.740] [http-nio-45678-exec-3] [ERROR] [.g.t.c.transaction.demo3.UserService:37  ] - create sub user error:invalid status
[22:57:21.740] [http-nio-45678-exec-3] [DEBUG] [o.s.orm.jpa.JpaTransactionManager       :741 ] - Initiating transaction commit
[22:57:21.740] [http-nio-45678-exec-3] [DEBUG] [o.s.orm.jpa.JpaTransactionManager       :529 ] - Committing JPA transaction on EntityManager [SessionImpl(1794007607<open>)]
[22:57:21.743] [http-nio-45678-exec-3] [DEBUG] [o.s.orm.jpa.JpaTransactionManager       :620 ] - Closing JPA EntityManager [SessionImpl(1794007607<open>)] after transaction
[22:57:21.743] [http-nio-45678-exec-3] [ERROR] [t.d.TransactionPropagationController:33  ] - createUserWrong2 failed, reason:Transaction silently rolled back because it has been marked as rollback-only
org.springframework.transaction.UnexpectedRollbackException: Transaction silently rolled back because it has been marked as rollback-only
...
```

需要注意以下几点：

- 如第1行所示，对createUserWrong2方法开启了异常处理；
- 如第5行所示，子方法因为出现了运行时异常，标记当前事务为回滚；
- 如第7行所示，主方法的确捕获了异常打印出了create sub user error字样；
- 如第9行所示，主方法提交了事务；
- 奇怪的是，如第11行和12行所示，**Controller里出现了一个UnexpectedRollbackException，异常描述提示最终这个事务回滚了，而且是静默回滚的**。之所以说是静默，是因为createUserWrong2方法本身并没有出异常，只不过提交后发现子方法已经把当前事务设置为了回滚，无法完成提交。

这挺反直觉的。**我们之前说，出了异常事务不一定回滚，这里说的却是不出异常，事务也不一定可以提交**。原因是，主方法注册主用户的逻辑和子方法注册子用户的逻辑是同一个事务，子逻辑标记了事务需要回滚，主逻辑自然也不能提交了。

看到这里，修复方式就很明确了，想办法让子逻辑在独立事务中运行，也就是改一下SubUserService注册子用户的方法，为注解加上propagation = Propagation.REQUIRES\_NEW来设置REQUIRES\_NEW方式的事务传播策略，也就是执行到这个方法时需要开启新的事务，并挂起当前事务：

```
@Transactional(propagation = Propagation.REQUIRES_NEW)
public void createSubUserWithExceptionRight(UserEntity entity) {
    log.info("createSubUserWithExceptionRight start");
    userRepository.save(entity);
    throw new RuntimeException("invalid status");
}
```

主方法没什么变化，同样需要捕获异常，防止异常漏出去导致主事务回滚，重新命名为createUserRight：

```
@Transactional
public void createUserRight(UserEntity entity) {
    createMainUser(entity);
    try{
        subUserService.createSubUserWithExceptionRight(entity);
    } catch (Exception ex) {
        // 捕获异常，防止主方法回滚
        log.error("create sub user error:{}", ex.getMessage());
    }
}
```

改造后，重新运行程序可以看到如下的关键日志：

- 第1行日志提示我们针对createUserRight方法开启了主方法的事务；
- 第2行日志提示创建主用户完成；
- 第3行日志可以看到主事务挂起了，开启了一个新的事务，针对createSubUserWithExceptionRight方案，也就是我们的创建子用户的逻辑；
- 第4行日志提示子方法事务回滚；
- 第5行日志提示子方法事务完成，继续主方法之前挂起的事务；
- 第6行日志提示主方法捕获到了子方法的异常；
- 第8行日志提示主方法的事务提交了，随后我们在Controller里没看到静默回滚的异常。

```
[23:17:20.935] [http-nio-45678-exec-1] [DEBUG] [o.s.orm.jpa.JpaTransactionManager       :370 ] - Creating new transaction with name [org.geekbang.time.commonmistakes.transaction.demo3.UserService.createUserRight]: PROPAGATION_REQUIRED,ISOLATION_DEFAULT
[23:17:21.079] [http-nio-45678-exec-1] [INFO ] [.g.t.c.transaction.demo3.UserService:55  ] - createMainUser finish
[23:17:21.082] [http-nio-45678-exec-1] [DEBUG] [o.s.orm.jpa.JpaTransactionManager       :420 ] - Suspending current transaction, creating new transaction with name [org.geekbang.time.commonmistakes.transaction.demo3.SubUserService.createSubUserWithExceptionRight]
[23:17:21.153] [http-nio-45678-exec-1] [DEBUG] [o.s.orm.jpa.JpaTransactionManager       :834 ] - Initiating transaction rollback
[23:17:21.160] [http-nio-45678-exec-1] [DEBUG] [o.s.orm.jpa.JpaTransactionManager       :1009] - Resuming suspended transaction after completion of inner transaction
[23:17:21.161] [http-nio-45678-exec-1] [ERROR] [.g.t.c.transaction.demo3.UserService:49  ] - create sub user error:invalid status
[23:17:21.161] [http-nio-45678-exec-1] [DEBUG] [o.s.orm.jpa.JpaTransactionManager       :741 ] - Initiating transaction commit
[23:17:21.161] [http-nio-45678-exec-1] [DEBUG] [o.s.orm.jpa.JpaTransactionManager       :529 ] - Committing JPA transaction on EntityManager [SessionImpl(396441411<open>)]
```

运行测试程序看到如下结果，getUserCount得到的用户数量为1，代表只有一个用户也就是主用户注册完成了，符合预期：

![](https://static001.geekbang.org/resource/image/3b/f8/3bd9c32b5144025f1a2de5b4ec436ff8.png?wh=1188%2A216)

## 重点回顾

今天，我针对业务代码中最常见的使用数据库事务的方式，即Spring声明式事务，与你总结了使用上可能遇到的三类坑，包括：

第一，因为配置不正确，导致方法上的事务没生效。我们务必确认调用@Transactional注解标记的方法是public的，并且是通过Spring注入的Bean进行调用的。

第二，因为异常处理不正确，导致事务虽然生效但出现异常时没回滚。Spring默认只会对标记@Transactional注解的方法出现了RuntimeException和Error的时候回滚，如果我们的方法捕获了异常，那么需要通过手动编码处理事务回滚。如果希望Spring针对其他异常也可以回滚，那么可以相应配置@Transactional注解的rollbackFor和noRollbackFor属性来覆盖其默认设置。

第三，如果方法涉及多次数据库操作，并希望将它们作为独立的事务进行提交或回滚，那么我们需要考虑进一步细化配置事务传播方式，也就是@Transactional注解的Propagation属性。

可见，正确配置事务可以提高业务项目的健壮性。但，又因为健壮性问题往往体现在异常情况或一些细节处理上，很难在主流程的运行和测试中发现，导致业务代码的事务处理逻辑往往容易被忽略，因此**我在代码审查环节一直很关注事务是否正确处理**。

如果你无法确认事务是否真正生效，是否按照预期的逻辑进行，可以尝试打开Spring的部分Debug日志，通过事务的运作细节来验证。也建议你在单元测试时尽量覆盖多的异常场景，这样在重构时，也能及时发现因为方法的调用方式、异常处理逻辑的调整，导致的事务失效问题。

今天用到的代码，我都放在了GitHub上，你可以点击[这个链接](https://github.com/JosephZhu1983/java-common-mistakes)查看。

## 思考与讨论

1. 考虑到Demo的简洁，文中所有数据访问使用的都是Spring Data JPA。国内大多数互联网业务项目是使用MyBatis进行数据访问的，使用MyBatis配合Spring的声明式事务也同样需要注意文中提到的这些点。你可以尝试把今天的Demo改为MyBatis做数据访问实现，看看日志中是否可以体现出这些坑。
2. 在第一节中我们提到，如果要针对private方法启用事务，动态代理方式的AOP不可行，需要使用静态织入方式的AOP，也就是在编译期间织入事务增强代码，可以配置Spring框架使用AspectJ来实现AOP。你能否参阅Spring的文档“[Using @Transactional with AspectJ](https://docs.spring.io/spring/docs/current/spring-framework-reference/data-access.html#transaction-declarative-aspectj)”试试呢？注意：AspectJ配合lombok使用，还可能会踩一些坑。

有关数据库事务，你还遇到过其他坑吗？我是朱晔，欢迎在评论区与我留言分享，也欢迎你把这篇文章分享给你的朋友或同事，一起交流。
<div><strong>精选留言（15）</strong></div><ul>
<li><span>Darren</span> 👍（59） 💬（8）<p>AspectJ与lombok，都是字节码层面进行增强，在一起使用时会有问题，根据AspectJ维护者Andy Clement的当前答案是由于ECJ（Eclipse Compiler for Java）软件包存在问题在AspectJ编译器基础结构中包含和重命名。
解决问题可以参考下面连接：
http:&#47;&#47;aspectj.2085585.n4.nabble.com&#47;AspectJ-with-Lombok-td4651540.html
https:&#47;&#47;stackoverflow.com&#47;questions&#47;41910007&#47;lombok-and-aspectj

分享一个使用lombok的坑：
之前为了set赋值方便，在VO或者DTO上使用了@Accessors(chain=true)，这样就可以链式赋值，但是在动态通过内省获取set方法进行赋值时，是获取不到对应的set方法，因为默认的set方法返回值是void，但是加了@Accessors(chain=true)之后，set方法的返回值变成了this，这样通过内省就获取到对应的set方法了，通过去掉@Accessors(chain=true)即可实现，通过内省动态给属性赋值。</p>2020-03-23</li><br/><li><span>hanazawakana</span> 👍（47） 💬（4）<p>否则只有定义在 public 方法上的 @Transactional 才能生效。这里一定要用public吗，用protected不行吗，protected在子类中应该也可见啊，是因为包不同吗</p>2020-03-21</li><br/><li><span>Seven.Lin澤耿</span> 👍（46） 💬（1）<p>我还遇到一个坑，就是子方法使用了REQUIRES_NEW，但是业务逻辑需要的数据是来源于父方法的，也就是父方法还没提交，子方法获取不到。当时的解决方法是把事务隔离级别改成RC，现在回想起来，不知道这种解决方法是否正确？</p>2020-03-22</li><br/><li><span>Seven.Lin澤耿</span> 👍（26） 💬（8）<p>老师，可以问一下为啥国内大多数公司使用MyBatis呢？是为了更加接近SQL吗？难倒国外业务不会遇到复杂的场景吗？</p>2020-03-22</li><br/><li><span>看不到de颜色</span> 👍（25） 💬（1）<p>Spring默认事务采用动态代理方式实现。因此只能对public进行增强（考虑到CGLib和JDKProxy兼容，protected也不支持）。在使用动态代理增强时，方法内调用也可以考虑采用AopContext.currentProxy()获取当前代理类。</p>2020-03-29</li><br/><li><span>九时四</span> 👍（19） 💬（8）<p>老师您好，有个数据库事务和spring事务的问题想请教下（我是一个入职半年的菜鸟）。
业务场景：为了实现同一个时间的多个请求，只有一个请求生效，在数据库字段上加了一个字段（signature_lock）标识锁状态。（没有使用redis锁之类的中间件，只讨论数据库事务和Spring的事务，以下的请求理解为同时请求）

1.在数据库层面，通过sql语句直接操作数据库，数据库事务隔离级别为可重复读：

-- 请求1
show VARIABLES like &#39;tx_isolation&#39;;
START TRANSACTION;
select * from subscribe_info where id = 29;
-- update语句只有一个请求可以执行，另一个请求在等待
update trade_deal_subscribe_info set signature_lock =1 where id = 1 and signature_lock = 0;
commit;

-- 请求2
show VARIABLES like &#39;tx_isolation&#39;;
START TRANSACTION;
select * from trade_deal_subscribe_info where id = 29;
-- update语句只有一个请求可以执行，另一个请求在等待
update subscribe_info set signature_lock =1 where id = 1 and signature_lock = 0;
commit;

两个请求中只有一个可以执行成功update语句，将signature_lock更新为1。



2.在代码层面按照在数据库层面的逻辑，service层的伪代码如下：
public void test(ParamDto paramDto) {
 &#47;&#47;取数据
 Data data = getByParamDto(paramDto);
 &#47;&#47; 尝试加锁,返回1表示加锁成功
 Integer lockStatus = lockData(paramDto);
 &#47;&#47; 加锁失败直接返回
 if(!Objects.equals(1,lockStatus)){
  return;
 }
 try{
   &#47;&#47; 处理业务代码，大概2到3秒 
   handle();
 }catch(Exception e){
 
 } finally{
   &#47;&#47; 释放锁
   releaseLock(paramDto);
 }
}


按照这样的方式，在方法上面不加注解的情况下，执行结果与在写sql的结果是一致的，两个请求只有一个可以执行成功；加上@Transactional(rollbackFor = Exception.class, propagation = Propagation.REQUIRED)之后，两个请求都可以拿到锁。

疑问是，Spring的事务和数据库的事务有什么关系，加上事务注解后，为什么和数据库的结果不一致。</p>2020-03-21</li><br/><li><span>火很大先生</span> 👍（15） 💬（1）<p>    @Transactional
    public int createUserRight(String name) throws IOException {
        try {
            userRepository.save(new UserEntity(name));
            throw new RuntimeException(&quot;error&quot;);
        } catch (Exception ex) {
            log.error(&quot;create user failed because {}&quot;, ex.getMessage());
            TransactionAspectSupport.currentTransactionStatus().setRollbackOnly();
        }
        return userRepository.findByName(name).size();
    }
请教老师，我这种写法，控制台打出了Initiating transaction rollback 但是数据库还是存上了数据，没有回滚，是因为findByName 这个查询语句的默认commit给提交了吗</p>2020-04-10</li><br/><li><span>王刚</span> 👍（6） 💬（2）<p>老师问个问题，您说得@Transactional事物回滚，只有是RuntimeException 或error时，才会回滚；
但是我在做测试时，发现@Transactional有一个rollbackFor属性，该属性可以指定什么异常回滚，如果@Transactional 不指定rollbackFor，默认得是RuntimeException？</p>2020-03-26</li><br/><li><span>汝林外史</span> 👍（6） 💬（5）<p>老师，创建主子用户那个业务，应该是子用户创建失败不影响主用户，但是主用户失败应该子用户也要回滚吧？如果是这样，那传播机制是不是应该用Propagation.NESTED</p>2020-03-24</li><br/><li><span>Yanni</span> 👍（5） 💬（5）<p>要注意，@Transactional 与 @Async注解不能同时在一个方法上使用, 这样会导致事物不生效。</p>2020-04-10</li><br/><li><span>magic</span> 👍（5） 💬（1）<p>老师能补充下对私有方法事务的代码示例吗？</p>2020-03-28</li><br/><li><span>汝林外史</span> 👍（5） 💬（1）<p>很明显，this 调用因为没有走代理，事务没有在 createUserPublic 方法上生效，只在 Repository 的 save 方法层面生效。
createUserPublic这个方法不是本来就一个save操作吗，既然save层面生效了，那这个方法的事务难道不也就生效了吗？</p>2020-03-23</li><br/><li><span>COLDLY</span> 👍（4） 💬（2）<p>请问如果仅是select语句，需要加事务吗</p>2020-04-07</li><br/><li><span>张珮磊想静静</span> 👍（4） 💬（2）<p>如果一个事务里面操作了不同的数据库，回滚操作是不是就得自己写补偿的重试了？</p>2020-03-26</li><br/><li><span>nimil</span> 👍（3） 💬（2）<p>前几天还真出现了个事务不生效的问题，于是对着文章仔细review了一下代码，发现也没文中说的那些毛病，最后排查到是事务管理器只配置了一个数据库，而我是在另一个数据库进行的数据操作，所以事务不生效了，最后添加另一个数据库的事务管理器事务就生效了</p>2020-06-11</li><br/>
</ul>